{
 "cells": [
  {
   "cell_type": "code",
   "execution_count": 2,
   "metadata": {},
   "outputs": [
    {
     "ename": "ModuleNotFoundError",
     "evalue": "No module named 'geoplotlib'",
     "output_type": "error",
     "traceback": [
      "\u001b[1;31m---------------------------------------------------------------------------\u001b[0m",
      "\u001b[1;31mModuleNotFoundError\u001b[0m                       Traceback (most recent call last)",
      "Cell \u001b[1;32mIn[2], line 1\u001b[0m\n\u001b[1;32m----> 1\u001b[0m \u001b[38;5;28;01mimport\u001b[39;00m \u001b[38;5;21;01mgeoplotlib\u001b[39;00m\n\u001b[0;32m      2\u001b[0m thedata \u001b[38;5;241m=\u001b[39m geoplotlib\u001b[38;5;241m.\u001b[39mutils\u001b[38;5;241m.\u001b[39mread_csv(\u001b[38;5;124m'\u001b[39m\u001b[38;5;124mhelloworld.csv\u001b[39m\u001b[38;5;124m'\u001b[39m)\n\u001b[0;32m      3\u001b[0m geoplotlib\u001b[38;5;241m.\u001b[39mdot(thedata)\n",
      "\u001b[1;31mModuleNotFoundError\u001b[0m: No module named 'geoplotlib'"
     ]
    }
   ],
   "source": [
    "import geoplotlib\n",
    "thedata = geoplotlib.utils.read_csv('helloworld.csv')\n",
    "geoplotlib.dot(thedata)\n",
    "geoplotlib.show()"
   ]
  },
  {
   "cell_type": "code",
   "execution_count": 1,
   "metadata": {},
   "outputs": [
    {
     "name": "stdout",
     "output_type": "stream",
     "text": [
      "Collecting geoplotlib\n",
      "  Downloading geoplotlib-0.3.2.tar.gz (22 kB)\n",
      "  Preparing metadata (setup.py): started\n",
      "  Preparing metadata (setup.py): finished with status 'error'\n",
      "Note: you may need to restart the kernel to use updated packages.\n"
     ]
    },
    {
     "name": "stderr",
     "output_type": "stream",
     "text": [
      "  error: subprocess-exited-with-error\n",
      "  \n",
      "  × python setup.py egg_info did not run successfully.\n",
      "  │ exit code: 1\n",
      "  ╰─> [1 lines of output]\n",
      "      error in geoplotlib setup command: use_2to3 is invalid.\n",
      "      [end of output]\n",
      "  \n",
      "  note: This error originates from a subprocess, and is likely not a problem with pip.\n",
      "error: metadata-generation-failed\n",
      "\n",
      "× Encountered error while generating package metadata.\n",
      "╰─> See above for output.\n",
      "\n",
      "note: This is an issue with the package mentioned above, not pip.\n",
      "hint: See above for details.\n"
     ]
    }
   ],
   "source": [
    "%pip install geoplotlib"
   ]
  }
 ],
 "metadata": {
  "kernelspec": {
   "display_name": ".svenv",
   "language": "python",
   "name": "python3"
  },
  "language_info": {
   "codemirror_mode": {
    "name": "ipython",
    "version": 3
   },
   "file_extension": ".py",
   "mimetype": "text/x-python",
   "name": "python",
   "nbconvert_exporter": "python",
   "pygments_lexer": "ipython3",
   "version": "3.10.11"
  }
 },
 "nbformat": 4,
 "nbformat_minor": 2
}
